scripts/grader_output_seed_636945.out
# Seed: 636945

# Grader STDOUT:
Engine stdout: S 11 AGDSAGSO 184 14 1944425560260766
Engine stdout: S 10 AGDSAGSO 62 5 1944425560381731
Engine stdout: S 26 AGFG 6 7 1944425561071015
Engine stdout: S 56 AGOD 265 14 1944425560653878
Engine stdout: S 90 AGOD 391 18 1944425561204616
Engine stdout: S 62 GOOS 460 14 1944425561224540
Engine stdout: B 15 GOOS 3 13 1944425560941979
Engine stdout: B 19 GODG 88 11 1944425561143161
Engine stdout: S 9 GOOG 229 19 1944425561383772
Engine stdout: X 11 A 1944425561454884
Engine stdout: X 11 R 1944425561513066
Engine stdout: S 35 ADOX 362 20 1944425561488369
Engine stdout: S 70 GFGO 118 19 1944425561549084
Engine stdout: X 10 A 1944425561145560
Engine stdout: X 35 A 1944425561576010
Engine stdout: S 114 GFG 219 18 1944425561306317
Engine stdout: S 80 ADOX 314 17 1944425561616607
Engine stdout: X 9 A 1944425561586980
Engine stdout: X 90 A 1944425561652304
Engine stdout: B 86 AGOO 39 20 1944425561662669
Engine stdout: B 7 AGOO 301 8 1944425561653646
Engine stdout: B 118 GODG 233 4 1944425561704783
Engine stdout: X 86 A 1944425561726259
Engine stdout: X 86 R 1944425561785365
Engine stdout: X 70 A 1944425561768211
Engine stdout: E 62 2 1 460 5 1944425561829435
Engine stdout: X 2 R 1944425561856499
Engine stdout: S 24 AGDSAGSO 311 5 1944425561741577
Engine stdout: B 21 GDSOGSOG 152 2 1944425561916982
Engine stdout: B 43 AGOO 222 11 1944425561982833
Engine stdout: B 34 GOOS 318 6 1944425561975619
Engine stdout: B 76 AGOOD 489 13 1944425562043680
Engine stdout: B 115 GOOS 171 11 1944425561675954
Engine stdout: S 107 ADOX 119 20 1944425562110733
Engine stdout: B 45 AGOD 179 11 1944425561121506
Engine stdout: E 45 25 1 179 11 1944425561920173
Engine stdout: S 25 AGOD 64 4 1944425562302862
Engine stdout: S 27 ADOX 498 4 1944425562063472
Engine stdout: S 132 AGDSAGSO 313 6 1944425561707723
Engine stdout: S 131 AGOD 232 17 1944425562062257
Engine stdout: X 45 R 1944425562374698
Engine stdout: X 45 R 1944425562640505
Engine stdout: B 106 GDSOGSOG 103 5 1944425562014059
Engine stdout: B 60 GFG 131 19 1944425562614397
Engine stdout: S 126 AGDSAGSO 146 19 1944425562672628
Engine stdout: B 127 GOOS 111 11 1944425562741360
Engine stdout: X 27 A 1944425562481479
Engine stdout: S 3 GOSF 2 4 1944425562563845
Engine stdout: S 55 AGOZ 302 12 1944425562963864
Engine stdout: X 106 A 1944425562709674
Engine stdout: E 76 98 1 489 13 1944425562788852
Engine stdout: B 66 AGOZ 95 18 1944425563025341
Engine stdout: X 66 A 1944425563105013
Engine stdout: X 66 R 1944425563137776
Engine stdout: S 79 GOSF 235 2 1944425563150107
Engine stdout: E 26 119 1 6 7 1944425563174679
Engine stdout: B 119 AGFG 135 4 1944425563217364
Engine stdout: S 72 DOOG 46 7 1944425561347175
Engine stdout: E 25 93 1 64 4 1944425563317718
Engine stdout: E 131 93 1 232 15 1944425563341400
Engine stdout: X 93 R 1944425563353532
Engine stdout: X 15 A 1944425562407534
Engine stdout: B 59 GDSOGSOG 170 12 1944425563391997
Engine stdout: S 73 GOSF 400 5 1944425563416475
Engine stdout: B 96 GFGO 183 9 1944425562858868
Engine stdout: E 107 48 1 119 9 1944425562932411
Engine stdout: X 96 A 1944425563487783
Engine stdout: B 13 AGOO 448 11 1944425562361319
Engine stdout: E 72 17 1 46 7 1944425562795798
Engine stdout: S 23 GFGO 466 10 1944425563576590
Engine stdout: E 55 50 1 302 10 1944425563526755
Engine stdout: X 50 R 1944425563712708
Engine stdout: X 59 A 1944425563438892
Engine stdout: S 58 GFG 368 8 1944425563647140
Engine stdout: X 58 A 1944425563782719
Engine stdout: S 98 AGOOD 442 5 1944425563092032
Engine stdout: X 25 R 1944425563766347
Engine stdout: S 109 ADOX 181 10 1944425563826048
Engine stdout: S 104 GOOG 245 2 1944425563856452
Engine stdout: B 110 AGOOD 44 18 1944425563884906
Engine stdout: B 17 DOOG 242 11 1944425563735042
Engine stdout: X 98 A 1944425563912106
Engine stdout: X 3 A 1944425562992698
Engine stdout: X 17 A 1944425563976911
Engine stdout: X 17 R 1944425564053488
Engine stdout: B 54 AGOOD 233 5 1944425564037631
Engine stdout: S 103 GOOD 341 6 1944425564078412
Engine stdout: E 34 63 1 318 6 1944425564114524
Engine stdout: E 118 124 1 233 4 1944425563983414
Engine stdout: S 36 GOOD 256 5 1944425564137088
Engine stdout: B 122 AGOZ 85 18 1944425564147316
Engine stdout: S 51 ADOX 61 6 1944425564073430
Engine stdout: S 39 GOOG 496 10 1944425564242496
Engine stdout: E 51 37 1 61 6 1944425564287271
Engine stdout: X 103 A 1944425564239404
Engine stdout: B 12 GOOD 172 1 1944425564215448
Engine stdout: X 25 R 1944425563862968
Engine stdout: E 115 63 1 171 1 1944425564162100
Engine stdout: S 111 GOOG 132 8 1944425564379476
Engine stdout: B 20 AGOO 428 15 1944425564383366
Engine stdout: E 36 65 1 256 5 1944425564440012
Engine stdout: S 57 ADOX 380 9 1944425564310208
Engine stdout: B 65 GOOD 370 8 1944425564678399
Engine stdout: X 39 A 1944425564759430
Engine stdout: S 120 AGDSAGSO 454 10 1944425564881619
Engine stdout: E 55 1 2 302 2 1944425564947502
Engine stdout: B 1 AGOZ 363 1 1944425565026158
Engine stdout: B 82 GOOS 218 7 1944425564806056
Engine stdout: B 100 AGOO 152 15 1944425565107613
Engine stdout: X 37 R 1944425564509666
Engine stdout: X 57 A 1944425564945184
Engine stdout: X 39 R 1944425565155297
Engine stdout: E 13 33 1 448 11 1944425565157217
Engine stdout: S 53 DOOG 482 4 1944425565151766
Engine stdout: S 95 AGDSAGSO 166 5 1944425565165522
Engine stdout: X 33 R 1944425565180584
Engine stdout: E 126 14 1 146 5 1944425564686210
Engine stdout: X 95 A 1944425565183016
Engine stdout: E 114 133 1 219 16 1944425565189868
Engine stdout: X 14 R 1944425565191565
Engine stdout: B 47 ADOX 33 9 1944425565198462
Engine stdout: E 62 49 2 460 9 1944425565080355
Engine stdout: E 21 8 1 152 2 1944425564502908
Engine stdout: B 49 GOOS 470 9 1944425565258823
Engine stdout: S 8 GDSOGSOG 134 12 1944425565258657
Engine stdout: B 68 AGOZ 430 6 1944425565269042
Engine stdout: B 74 GODG 368 2 1944425565289503
Engine stdout: X 8 A 1944425565289584
Engine stdout: S 102 GFGO 478 12 1944425565296318
Engine stdout: B 22 DOOG 281 16 1944425564034958
Engine stdout: X 100 A 1944425565137525
Engine stdout: B 4 GOOS 357 2 1944425565092032
Engine stdout: B 123 GOSF 159 17 1944425565331359
Engine stdout: S 116 AGFG 350 5 1944425565334447
Engine stdout: X 4 A 1944425565338130
Engine stdout: X 22 A 1944425565340223
Engine stdout: X 65 A 1944425565346343
Engine stdout: B 5 AGOO 218 19 1944425565342626
Engine stdout: S 28 GOOG 17 6 1944425565349529
Engine stdout: B 40 AGOD 200 16 1944425565369099
Engine stdout: S 99 GOOS 396 13 1944425565261626
Engine stdout: B 29 AGOZ 121 5 1944425565317539
Engine stdout: B 108 GFGO 195 17 1944425565321166
Engine stdout: X 99 A 1944425565412745
Engine stdout: X 20 A 1944425564583527
Engine stdout: E 111 6 1 132 1 1944425565069964
Engine stdout: S 18 AGFG 234 6 1944425565133561
Engine stdout: E 18 52 1 234 6 1944425565245569
Engine stdout: S 16 AGOO 354 18 1944425565201022
Engine stdout: S 69 GOOG 450 13 1944425565484440
Engine stdout: E 71 92 1 267 19 1944425565501383
Engine stdout: E 1 30 1 363 1 1944425565081108
Engine stdout: B 31 DOOG 246 6 1944425565498797
Engine stdout: B 61 AGFG 275 4 1944425565497258
Engine stdout: E 68 30 1 430 6 1944425565527802
Engine stdout: X 18 R 1944425565529716
Engine stdout: E 108 81 1 195 3 1944425565532569
Engine stdout: E 28 41 1 17 6 1944425565386922
Engine stdout: S 44 AGFG 451 12 1944425565385908
Engine stdout: S 101 AGOZ 348 6 1944425565537041
Engine stdout: B 75 GODG 144 7 1944425565448486
Engine stdout: B 32 AGOZ 347 6 1944425565379271
Engine stdout: X 69 A 1944425565552819
Engine stdout: E 123 84 1 159 1 1944425565565213
Engine stdout: S 87 GDSOGSOG 456 4 1944425565437899
Engine stdout: E 32 30 1 347 4 1944425565535092
Engine stdout: B 129 AGFG 152 12 1944425565568933
Engine stdout: S 89 GOSF 404 10 1944425565540191
Engine stdout: B 52 AGFG 289 2 1944425565493290
Engine stdout: S 125 GFGO 424 6 1944425565591091
Engine stdout: S 71 GFGO 267 19 1944425565164565
Engine stdout: X 8 R 1944425565396693
Engine stdout: E 49 42 1 470 4 1944425565439570
