scripts/grader_output_seed_837482.out
# Seed: 837482

# Grader STDOUT:
Engine stdout: B 9 GOOG 27 4 1944161003331472
Engine stdout: B 35 GFGO 496 5 1944161003391701
Engine stdout: B 79 GODG 237 9 1944161003495025
Engine stdout: S 31 GOOD 258 5 1944161003511247
Engine stdout: X 9 A 1944161003532525
Engine stdout: B 83 DOOG 186 5 1944161003514684
Engine stdout: B 10 ADOX 342 9 1944161003521264
Engine stdout: S 101 GFG 437 11 1944161003543936
Engine stdout: B 66 GFG 404 15 1944161003549014
Engine stdout: X 101 A 1944161003567032
Engine stdout: E 35 89 1 496 3 1944161003575168
Engine stdout: S 74 AGOD 263 16 1944161003509022
Engine stdout: B 20 GOOS 238 3 1944161003572892
Engine stdout: S 81 AGDSAGSO 332 14 1944161003577487
Engine stdout: S 123 AGOD 368 20 1944161003580872
Engine stdout: B 87 AGOD 251 1 1944161003587966
Engine stdout: X 74 A 1944161003602165
Engine stdout: B 46 AGOZ 470 10 1944161003612009
Engine stdout: X 10 A 1944161003624184
Engine stdout: E 87 100 1 251 1 1944161003637128
Engine stdout: B 17 ADOX 49 11 1944161003630584
Engine stdout: B 112 AGOO 140 16 1944161003589199
Engine stdout: E 66 34 1 404 10 1944161003651790
Engine stdout: S 3 AGFG 44 5 1944161003655066
Engine stdout: B 60 GOOD 182 8 1944161003661265
Engine stdout: B 16 DOOG 126 10 1944161003677914
Engine stdout: E 79 114 1 237 2 1944161003689595
Engine stdout: E 66 68 2 404 5 1944161003694148
Engine stdout: S 100 AGOD 64 14 1944161003649067
Engine stdout: S 68 GFG 283 11 1944161003703219
Engine stdout: E 68 28 1 283 11 1944161003718851
Engine stdout: S 80 AGOD 451 12 1944161003718824
Engine stdout: E 46 19 1 470 10 1944161003728350
Engine stdout: B 54 AGOZ 465 18 1944161003678387
Engine stdout: B 104 AGOO 462 5 1944161003734173
Engine stdout: B 84 GODG 476 6 1944161003729576
Engine stdout: B 28 GFG 316 3 1944161003735564
Engine stdout: B 108 GOOD 71 7 1944161003744431
Engine stdout: X 84 A 1944161003748124
Engine stdout: B 127 ADOX 408 20 1944161003759710
Engine stdout: S 36 GOOG 342 16 1944161003670863
Engine stdout: X 54 A 1944161003742654
Engine stdout: B 128 GOSF 473 12 1944161003715224
Engine stdout: S 119 AGOOD 82 3 1944161003777288
Engine stdout: B 73 GOSF 33 10 1944161003779597
Engine stdout: B 110 GOSF 320 18 1944161003788143
Engine stdout: E 28 135 1 316 2 1944161003802772
Engine stdout: X 36 A 1944161003795032
Engine stdout: S 33 GDSOGSOG 401 9 1944161003764576
Engine stdout: E 119 71 1 82 3 1944161003820117
Engine stdout: B 71 AGOOD 211 3 1944161003827686
Engine stdout: S 19 AGOZ 81 9 1944161003788196
Engine stdout: X 71 A 1944161003840584
Engine stdout: E 35 50 2 496 2 1944161003859067
Engine stdout: B 5 GOOD 33 10 1944161003838889
Engine stdout: X 28 A 1944161003860485
Engine stdout: B 40 GFGO 35 7 1944161003854576
Engine stdout: X 33 A 1944161003875887
Engine stdout: S 98 AGDSAGSO 86 18 1944161003880261
Engine stdout: S 37 GDSOGSOG 380 16 1944161003794731
Engine stdout: S 50 GFGO 366 4 1944161003891331
Engine stdout: E 98 85 1 86 14 1944161003914125
Engine stdout: X 50 A 1944161003915896
Engine stdout: X 50 R 1944161003925406
Engine stdout: B 43 GOSF 373 2 1944161003922287
Engine stdout: E 128 1 1 473 12 1944161003941047
Engine stdout: S 59 GODG 322 7 1944161003886673
Engine stdout: E 43 1 1 373 1 1944161003958418
Engine stdout: S 91 AGOD 360 12 1944161003920736
Engine stdout: B 103 GDSOGSOG 139 13 1944161003964106
Engine stdout: B 12 GOOG 491 3 1944161003968796
Engine stdout: S 107 GFG 438 4 1944161003945799
Engine stdout: X 12 A 1944161003984479
Engine stdout: B 129 GOSF 218 13 1944161003981247
Engine stdout: S 56 GOOD 357 19 1944161003987819
Engine stdout: E 100 134 1 64 12 1944161004012843
Engine stdout: B 39 AGOO 19 16 1944161003994055
Engine stdout: S 124 AGOD 283 17 1944161003973269
Engine stdout: X 56 A 1944161004018898
Engine stdout: E 60 13 1 182 8 1944161003964257
Engine stdout: S 64 AGOD 257 16 1944161004029266
Engine stdout: E 108 13 1 71 7 1944161004048202
Engine stdout: E 5 13 1 33 1 1944161004070415
Engine stdout: S 27 GOOG 274 4 1944161004083211
Engine stdout: B 7 GOSF 314 10 1944161004058589
Engine stdout: B 116 AGOOD 130 6 1944161004063248
Engine stdout: X 7 A 1944161004107634
Engine stdout: E 19 14 1 81 5 1944161003997365
Engine stdout: B 76 GFGO 134 15 1944161004120940
Engine stdout: B 21 GOOS 406 5 1944161004082419
Engine stdout: E 20 82 1 238 3 1944161004054211
Engine stdout: X 21 A 1944161004138633
Engine stdout: X 7 R 1944161004130707
Engine stdout: E 5 48 2 33 9 1944161004150291
Engine stdout: B 97 GOOS 282 17 1944161004156468
Engine stdout: S 82 GOOS 39 10 1944161004155015
Engine stdout: B 2 AGOOD 355 18 1944161004147852
Engine stdout: S 48 GOOD 8 3 1944161004159372
Engine stdout: S 106 AGOOD 486 3 1944161004167621
Engine stdout: X 21 R 1944161004181737
Engine stdout: B 57 AGOOD 313 10 1944161004175522
Engine stdout: X 57 A 1944161004189530
Engine stdout: E 97 24 1 282 2 1944161004203659
Engine stdout: S 67 AGOZ 142 4 1944161004144650
Engine stdout: X 24 R 1944161004211873
Engine stdout: B 99 GFGO 22 4 1944161004203932
Engine stdout: E 100 63 2 64 2 1944161004220356
Engine stdout: X 67 A 1944161004216104
Engine stdout: B 125 AGOO 76 13 1944161004225201
Engine stdout: S 78 GOOD 139 1 1944161004230747
Engine stdout: E 97 23 2 282 14 1944161004213058
Engine stdout: X 125 A 1944161004231973
Engine stdout: B 63 AGOD 82 9 1944161004231369
Engine stdout: B 52 GDSOGSOG 177 10 1944161004253292
Engine stdout: X 63 A 1944161004266336
Engine stdout: X 24 R 1944161004276602
Engine stdout: E 37 90 1 380 11 1944161004271382
Engine stdout: E 98 6 2 86 4 1944161004290700
Engine stdout: S 8 GFG 318 7 1944161004270722
Engine stdout: S 109 AGFG 281 1 1944161004291960
Engine stdout: E 81 6 1 332 13 1944161004303062
Engine stdout: E 19 22 2 81 4 1944161004320599
Engine stdout: E 76 86 1 134 12 1944161004324276
Engine stdout: E 3 117 1 44 5 1944161004314092
Engine stdout: B 22 AGOZ 292 6 1944161004332645
Engine stdout: X 6 R 1944161004344925
Engine stdout: S 42 AGOZ 481 18 1944161004308963
Engine stdout: B 117 AGFG 234 7 1944161004349542
Engine stdout: S 49 GOOD 167 5 1944161004349864
Engine stdout: E 2 18 1 355 5 1944161004338118
Engine stdout: X 49 A 1944161004362213
Engine stdout: B 94 GFGO 329 17 1944161004332533
Engine stdout: X 13 R 1944161004251317
Engine stdout: S 61 DOOG 397 2 1944161004132173
Engine stdout: E 43 11 2 373 1 1944161004321874
Engine stdout: S 75 AGOO 470 16 1944161004358467
Engine stdout: S 96 AGOD 492 2 1944161004379594
Engine stdout: E 110 11 1 320 16 1944161004394280
Engine stdout: E 104 44 1 462 3 1944161004385194
Engine stdout: E 106 105 1 486 3 1944161004400172
Engine stdout: X 1 R 1944161004404294
Engine stdout: B 130 GODG 154 9 1944161004359436
Engine stdout: S 88 GOSF 488 7 1944161004411576
Engine stdout: S 126 GFGO 464 9 1944161004411266
Engine stdout: B 77 GOOG 142 5 1944161004395164
Engine stdout: S 111 GOOG 380 9 1944161004398814
Engine stdout: X 75 A 1944161004432197
Engine stdout: S 131 GOSF 396 10 1944161004430312
Engine stdout: S 45 GOOD 27 20 1944161004411224
Engine stdout: X 14 R 1944161004424746
Engine stdout: B 53 AGOOD 409 14 1944161004446929
Engine stdout: B 51 DOOG 44 10 1944161004454464
Engine stdout: S 25 GOOG 419 1 1944161004461928
Engine stdout: B 105 AGOOD 491 10 1944161004417240
Engine stdout: E 27 4 1 274 4 1944161004482534
Engine stdout: S 26 DOOG 196 2 1944161004375335
Engine stdout: X 96 A 1944161004438951
Engine stdout: B 62 AGDSAGSO 111 5 1944161004466521
Engine stdout: X 26 A 1944161004493445
Engine stdout: B 58 GOSF 211 14 1944161004471039
Engine stdout: S 29 GOOG 375 14 1944161004481708
Engine stdout: B 38 AGOO 320 14 1944161004479313
Engine stdout: S 118 AGOD 99 19 1944161004486893
Engine stdout: E 94 32 1 329 17 1944161004373489
Engine stdout: S 69 AGOZ 424 5 1944161004509023
Engine stdout: S 133 GOOG 296 19 1944161004497340
Engine stdout: X 26 R 1944161004504019
Engine stdout: X 53 A 1944161004501446
Engine stdout: E 121 55 1 306 9 1944161004537184
Engine stdout: S 30 AGOD 183 7 1944161004512805
Engine stdout: B 120 AGOOD 281 4 1944161004530948
