scripts/large_test_file.in
# seed: 636945
40
.
o
21 B 1 AGOZ 363 3
35 B 2 GOOS 479 5
16 S 3 GOSF 2 4
8 B 4 GOOS 357 2
11 B 5 AGOO 218 19
24 B 6 GOOG 482 1
22 B 7 AGOO 301 8
3 S 8 GDSOGSOG 134 14
35 C 2
32 S 9 GOOG 229 19
16 C 3
25 S 10 AGDSAGSO 62 5
30 S 11 AGDSAGSO 184 14
9 B 12 GOOD 172 1
15 B 13 AGOO 448 11
31 B 14 AGDSAGSO 303 5
39 B 15 GOOS 3 13
10 S 16 AGOO 354 18
25 C 10
1 B 17 DOOG 242 18
24 C 6
6 S 18 AGFG 234 6
30 B 19 GODG 88 11
38 B 20 AGOO 428 15
35 B 21 GDSOGSOG 152 2
17 B 22 DOOG 281 16
15 S 23 GFGO 466 10
8 C 4
22 S 24 AGDSAGSO 311 5
39 S 25 AGOD 64 15
19 S 26 AGFG 6 7
28 S 27 ADOX 498 4
28 C 27
8 S 28 GOOG 17 6
3 C 8
31 C 14
3 B 29 AGOZ 121 5
20 S 30 AGOZ 270 11
10 B 31 DOOG 246 6
8 B 32 AGOZ 347 6
5 S 33 AGOO 142 11
14 B 34 GOOS 318 6
29 S 35 ADOX 362 20
26 S 36 GOOD 256 5
4 B 37 ADOX 258 6
1 C 17
24 B 38 AGOD 394 14
26 S 39 GOOG 496 10
11 B 40 AGOD 200 16
11 B 41 GOOG 419 13
7 S 42 GOOS 125 4
35 B 43 AGOO 222 11
12 S 44 AGFG 451 12
37 B 45 AGOD 179 11
39 C 15
1 C 17
10 B 46 GODG 398 10
31 B 47 ADOX 33 9
4 C 37
27 B 48 ADOX 442 9
21 B 49 GOOS 470 18
27 B 50 AGOZ 337 10
1 S 51 ADOX 61 6
31 B 52 AGFG 289 8
4 S 53 DOOG 482 4
16 B 54 AGOOD 233 5
28 S 55 AGOZ 302 12
36 S 56 AGOD 265 14
26 S 57 ADOX 380 9
24 C 38
3 C 8
15 S 58 GFG 368 8
39 B 59 GDSOGSOG 170 12
18 B 60 GFG 131 19
0 B 61 AGFG 275 4
36 S 62 GOOS 460 14
16 S 63 GOOS 157 7
24 C 38
3 B 64 GOOS 62 15
16 B 65 GOOD 370 13
38 C 20
29 C 35
24 C 6
28 B 66 AGOZ 95 18
11 S 67 GFG 53 11
28 C 66
28 C 66
21 B 68 AGOZ 430 6
6 S 69 GOOG 450 13
32 S 70 GFGO 118 19
4 S 71 GFGO 267 19
36 S 72 DOOG 46 7
32 C 9
39 S 73 GOSF 400 5
21 B 74 GODG 368 2
38 B 75 GODG 144 7
15 C 58
22 B 76 AGOOD 489 13
3 B 77 GOSF 171 17
38 S 78 AGOD 252 17
28 S 79 GOSF 235 2
25 S 80 ADOX 314 17
0 S 81 GFGO 141 3
16 B 82 GOOS 218 7
38 S 83 DOOG 107 14
8 S 84 GOSF 34 1
8 S 85 AGOZ 292 18
29 B 86 AGOO 39 20
23 S 87 GDSOGSOG 456 4
3 B 88 ADOX 322 1
0 S 89 GOSF 404 10
29 C 86
19 S 90 AGOD 391 18
10 S 91 GOSF 217 12
6 B 92 GFGO 423 19
36 B 93 AGOD 493 19
27 C 50
37 C 45
23 S 94 GFGO 14 7
36 C 93
30 C 11
5 S 95 AGDSAGSO 166 5
2 B 96 GFGO 183 9
38 S 97 AGOZ 273 11
33 S 98 AGOOD 442 18
34 S 99 GOOS 396 13
6 C 18
16 B 100 AGOO 152 15
5 C 33
30 C 11
5 C 95
6 S 101 AGOZ 348 6
21 S 102 GFGO 478 12
36 S 103 GOOD 341 6
34 C 99
33 S 104 GOOG 245 2
38 S 105 AGOOD 263 4
35 B 106 GDSOGSOG 103 5
31 C 14
22 S 107 ADOX 119 20
10 C 91
21 B 108 GFGO 195 17
26 C 39
33 C 98
15 S 109 ADOX 181 10
15 B 110 AGOOD 44 18
9 S 111 GOOG 132 8
6 C 69
16 C 100
12 S 112 GOOS 304 20
20 B 113 GOOD 4 16
10 C 91
19 S 114 GFG 219 18
25 B 115 GOOS 171 11
16 S 116 AGFG 350 5
4 B 117 GFGO 402 9
3 C 88
29 C 86
39 C 59
32 B 118 GODG 233 4
28 B 119 AGFG 135 11
26 S 120 AGDSAGSO 454 10
39 C 25
37 C 45
4 B 121 GOSF 287 15
26 C 57
19 C 90
36 B 122 AGOZ 85 18
32 C 70
17 B 123 GOSF 159 17
33 S 124 GODG 186 4
26 C 39
0 S 125 GFGO 424 6
2 C 96
36 C 103
37 S 126 AGDSAGSO 146 19
17 C 22
3 C 88
37 B 127 GOOS 111 11
35 C 106
24 C 6
38 C 105
39 C 25
38 S 128 GOOS 146 16
6 B 129 AGFG 152 12
24 S 130 ADOX 395 4
16 C 65
14 S 131 AGOD 232 17
7 C 42
19 S 132 AGDSAGSO 313 6
10 C 16
5 B 133 GFG 302 16
x
